### 수집기 측에서 예외처리하기
예외는 `collect`를 하는 수집기 측에서도 try-catch 식을 이용해 할 수 있다.

~~~kotlin
fun main() = runBlocking {
   try {
       simple().collect { value -> 
           println(value)
           check(value <= 1) { "Collected $value" }
       }
   } catch(e: Throwable) {
        println("Caught $e")   
   }
}

fun simple(): Flow<Int> = flow {
    for(i in 1..3) {
        println("emit : $i")
        emit(i)
    }
}
~~~

수집기 측에서 try~catch로 간단하게 예외를 처리할 수 있다.<br>

### 모든 예외는 처리가능
어느 곳에서 발생한 예외라도 처리가 가능합니다.

~~~kotlin
fun main() = runBlocking<Unit> {
    try {
        simple().collect { value -> println(value) }
    } catch(e: Throwable) {
        println("Caught $e")
    }
}

fun simple(): Flow<String> = 
	flow {
        for(i in 1..3) {
            println("Emitting $i")
            emit(i)
        }
    }.map { value -> 
        check(value <= 1) { "Crashed on $value" }
        "string $value"
    }
~~~

simple() 함수에서 에러가 났지만, main 함수에서도 에러를 잡을 수 있다.<br>

### 예외 투명성

빌더 코드 블록 내에서 예외를 처리하는 것은 예외 투명성을 어기는 것이다. 왜냐면 플로우 내부에서 예외를 처리하면 밖에서 예외가 발생했는지 알 수 없기 때문이다.<br>
플로우에서 catch 연산자를 이용해서 예외를 처리하는것이 빌더 코드블록에서 예외를 처리하는거 보다 훨씬 낫다.<br>
`catch` 블록에서 예외를 새로운 데이터로 만들어 `emit`을 하거나, 다시 예외를 던지거나, 로그를 남길 수 있다.

~~~kotlin
fun main() = runBlocking<Unit> {
    simple()
    	.catch { e -> emit("Caught $e")} // emit on exception 예외가 발생하면 호출이 된다.
        .collect { value -> println(value) }
}

fun simple(): Flow<String> = 
	flow {
        for(i in 1..3) {
            println("Emitting $i")
            emit(i)
        }
    }.map { value -> 
        check(value <= 1) { "Crashed on $value" }
        "string $value"
    }
~~~

### catch 투명성
`catch` 연산자는 업스트림(catch 연산자를 쓰기 전의 코드)에만 영향을 미치고 다운스트림에는 영향을 미치지 않는다. 이를 catch의 투명성이라 한다.

~~~kotlin
fun main() = runBlocking<Unit> {
    simple()
    	.catch { e -> println("Cauht $e")} // simple을 호출하는 곳에선 영향을 미칠 수 있다.
        // catch를 기준으로 위에있는건(simple())업 스트림 아래에 있는건 다운스트림.
        .collect { value -> // collect부분은 다운스트림이기 때문에 예외를 처리할 수 없다.
            check(value <= 1) { "Collected $value" }
            println(value)
        }
}

fun simple(): Flow<Int> = flow { // 플로우에서 예외를 발생하는건 main에 catch에서 다룰 수 있다.
    for(i in 1..3){
        println("Emitting $i")
        emit(i)
    }
}
~~~
