### 명령형 finally 블록
완료를 처리하는 방법 중의 하나는 명령형의 방식으로 `finally` 블록을 이용하는 것이다.

~~~kotlin
fun main() = runBlocking<Unit> {
    try {
        simple().collect { value -> println(value) }
    } finally {
        println("Done")
    }
}

fun simple(): Flow<Int> = (1..3).asFlow()
~~~

### 선언적으로 완료 처리하기
`onCompletion` 연산자를 선언해서 완료를 처리할 수 있다. 

~~~kotlin
fun main() = runBlocking<Unit> {
    simple()
    	.onCompletion { println("Done")}
        .collect { it -> println(it) }
}

fun simple(): Flow<Int> = (1..3).asFlow()
~~~

실행결과 : <br>
1<br>
2<br>
3<br>
Done<br>

~~~kotlin
fun main() = runBlocking<Unit> {
    simple()
    	.map {
            if(it > 2){
                throw IllegalStateException()
            }
            it + 1
        }
        .catch { e -> emit(-99)}
    	.onCompletion { println("Done")}
        .collect { it -> println(it) }
}

fun simple(): Flow<Int> = (1..3).asFlow()
~~~

실행결과 : <br>
2<br>
3<br>
-99<br>
Done<br>

### onCompletion의 장점
`onCompletion`은 종료 처리를 할 때 예외가 발생되었는지 여부를 알 수 있다. try~catch~finally에서는 catch에선 확인이 가능하지만<br>
finally에선 확인이 불가능하다. 이것이 onCompletion의 장점이다.

~~~kotlin
fun main() = runBlocking<Unit> {
    simple()
    // cause로 예외발생 여부를 알 수 있다.
    // 문제가 존재할 경우 cause는 값이 들어가게되어서 null이 아니게 된다.
    	.onCompletion { cause -> if(cause != null) println("Flow completed exception") else println("flow completed")}
        .catch { cause -> println("Caught exception")}
        .collect { it -> println(it) }
}

fun simple(): Flow<Int> = flow {
    emit(1)
    throw RuntimeException()
}
~~~
